Workbook

Sheet Dashboard
A1: Restaurant Weekly Operations Dashboard
P2: LY Week Range
D3: Instructions: | P3: =IF(AND(ISNUMBER($B$4),ISNUMBER($B$5)),TEXT(IF(ISNUMBER($B$4),DATE(YEAR($B$4-WEEKDAY($B$4,2)+4)-1,1,4)-WEEKDAY(DATE(YEAR($B$4-WEEKDAY($B$4,2)+4)-1,1,4),2)+1+7*(WEEKNUM($B$4-WEEKDAY($B$4,2)+4,2)-1),""),"yyyy-mm-dd")&" - "&TEXT(IF(ISNUMBER($B$5),DATE(YEAR($B$5-WEEKDAY($B$5,2)+4)-1,1,4)-WEEKDAY(DATE(YEAR($B$5-WEEKDAY($B$5,2)+4)-1,1,4),2)+1+7*(WEEKNUM($B$5-WEEKDAY($B$5,2)+4,2)-1)+6,""),"yyyy-mm-dd"),"")
A4: Week Start: | B4: 46023 | D4: Update B4 (start) and B5 (end) with date range
A5: Week End: | B5: 46029 | D5: Dashboard will auto-calculate comparisons
A7: NET SALES BY CATEGORY
A8: Category | B8: This Week | C8: Last Week | D8: Last Year Same Week | E8: Target % | F8: Actual % | G8: % vs Target | H8: Status
A9: Food | B9: =IFERROR(SUMIFS(Sales_Category!$D:$D, Sales_Category!$A:$A, ">="&$B$4, Sales_Category!$A:$A, "<="&$B$5, Sales_Category!$B:$B, "Food"), 0) | C9: =IFERROR(SUMIFS(Sales_Category!$D:$D, Sales_Category!$A:$A, ">="&($B$4-7), Sales_Category!$A:$A, "<="&($B$5-7), Sales_Category!$B:$B, "Food"), 0) | D9: =IFERROR(SUMIFS(Sales_Category!$D:$D, Sales_Category!$A:$A, ">="&IF(ISNUMBER($B$4), (IF(ISNUMBER($B$4),DATE(YEAR($B$4-WEEKDAY($B$4,2)+4)-1,1,4)-WEEKDAY(DATE(YEAR($B$4-WEEKDAY($B$4,2)+4)-1,1,4),2)+1+7*(WEEKNUM($B$4-WEEKDAY($B$4,2)+4,2)-1),"")), ""), Sales_Category!$A:$A, "<="&IF(ISNUMBER($B$5), (IF(ISNUMBER($B$5),DATE(YEAR($B$5-WEEKDAY($B$5,2)+4)-1,1,4)-WEEKDAY(DATE(YEAR($B$5-WEEKDAY($B$5,2)+4)-1,1,4),2)+1+7*(WEEKNUM($B$5-WEEKDAY($B$5,2)+4,2)-1)+6,"")), ""), Sales_Category!$B:$B, "Food"), 0) | E9: 0.6 | F9: =IFERROR(B9/SUMIFS(Sales_Category!$D:$D, Sales_Category!$A:$A, ">="&$B$4, Sales_Category!$A:$A, "<="&$B$5), 0) | G9: =IFERROR(F9-E9, 0) | H9: =IF(AND(F9<>"", E9<>""), IF(F9<=E9*1.05, "OK", IF(F9<=E9*1.15, "WARNING", "OFF")), "")
A10: Liquor (Incl. Wine) | B10: =IFERROR(SUMIFS(Sales_Category!$D:$D, Sales_Category!$A:$A, ">="&$B$4, Sales_Category!$A:$A, "<="&$B$5, Sales_Category!$B:$B, "Liquor") + SUMIFS(Sales_Category!$D:$D, Sales_Category!$A:$A, ">="&$B$4, Sales_Category!$A:$A, "<="&$B$5, Sales_Category!$B:$B, "Wine"), 0) | C10: =IFERROR(SUMIFS(Sales_Category!$D:$D, Sales_Category!$A:$A, ">="&($B$4-7), Sales_Category!$A:$A, "<="&($B$5-7), Sales_Category!$B:$B, "Liquor") + SUMIFS(Sales_Category!$D:$D, Sales_Category!$A:$A, ">="&($B$4-7), Sales_Category!$A:$A, "<="&($B$5-7), Sales_Category!$B:$B, "Wine"), 0) | D10: =IFERROR(SUMIFS(Sales_Category!$D:$D, Sales_Category!$A:$A, ">="&IF(ISNUMBER($B$4), (IF(ISNUMBER($B$4),DATE(YEAR($B$4-WEEKDAY($B$4,2)+4)-1,1,4)-WEEKDAY(DATE(YEAR($B$4-WEEKDAY($B$4,2)+4)-1,1,4),2)+1+7*(WEEKNUM($B$4-WEEKDAY($B$4,2)+4,2)-1),"")), ""), Sales_Category!$A:$A, "<="&IF(ISNUMBER($B$5), (IF(ISNUMBER($B$5),DATE(YEAR($B$5-WEEKDAY($B$5,2)+4)-1,1,4)-WEEKDAY(DATE(YEAR($B$5-WEEKDAY($B$5,2)+4)-1,1,4),2)+1+7*(WEEKNUM($B$5-WEEKDAY($B$5,2)+4,2)-1)+6,"")), ""), Sales_Category!$B:$B, "Liquor") + SUMIFS(Sales_Category!$D:$D, Sales_Category!$A:$A, ">="&IF(ISNUMBER($B$4), (IF(ISNUMBER($B$4),DATE(YEAR($B$4-WEEKDAY($B$4,2)+4)-1,1,4)-WEEKDAY(DATE(YEAR($B$4-WEEKDAY($B$4,2)+4)-1,1,4),2)+1+7*(WEEKNUM($B$4-WEEKDAY($B$4,2)+4,2)-1),"")), ""), Sales_Category!$A:$A, "<="&IF(ISNUMBER($B$5), (IF(ISNUMBER($B$5),DATE(YEAR($B$5-WEEKDAY($B$5,2)+4)-1,1,4)-WEEKDAY(DATE(YEAR($B$5-WEEKDAY($B$5,2)+4)-1,1,4),2)+1+7*(WEEKNUM($B$5-WEEKDAY($B$5,2)+4,2)-1)+6,"")), ""), Sales_Category!$B:$B, "Wine"), 0) | E10: 0.4 | F10: =IFERROR(B10/SUMIFS(Sales_Category!$D:$D, Sales_Category!$A:$A, ">="&$B$4, Sales_Category!$A:$A, "<="&$B$5), 0) | G10: =IFERROR(F10-E10, 0) | H10: =IF(AND(F10<>"", E10<>""), IF(F10<=E10*1.05, "OK", IF(F10<=E10*1.15, "WARNING", "OFF")), "")
A11: Bottled Beer | B11: =IFERROR(SUMIFS(Sales_Category!$D:$D, Sales_Category!$A:$A, ">="&$B$4, Sales_Category!$A:$A, "<="&$B$5, Sales_Category!$B:$B, "Bottled Beer"), 0) | C11: =IFERROR(SUMIFS(Sales_Category!$D:$D, Sales_Category!$A:$A, ">="&($B$4-7), Sales_Category!$A:$A, "<="&($B$5-7), Sales_Category!$B:$B, "Bottled Beer"), 0) | D11: =IFERROR(SUMIFS(Sales_Category!$D:$D, Sales_Category!$A:$A, ">="&IF(ISNUMBER($B$4), (IF(ISNUMBER($B$4),DATE(YEAR($B$4-WEEKDAY($B$4,2)+4)-1,1,4)-WEEKDAY(DATE(YEAR($B$4-WEEKDAY($B$4,2)+4)-1,1,4),2)+1+7*(WEEKNUM($B$4-WEEKDAY($B$4,2)+4,2)-1),"")), ""), Sales_Category!$A:$A, "<="&IF(ISNUMBER($B$5), (IF(ISNUMBER($B$5),DATE(YEAR($B$5-WEEKDAY($B$5,2)+4)-1,1,4)-WEEKDAY(DATE(YEAR($B$5-WEEKDAY($B$5,2)+4)-1,1,4),2)+1+7*(WEEKNUM($B$5-WEEKDAY($B$5,2)+4,2)-1)+6,"")), ""), Sales_Category!$B:$B, "Bottled Beer"), 0) | E11: 0 | F11: =IFERROR(B11/SUMIFS(Sales_Category!$D:$D, Sales_Category!$A:$A, ">="&$B$4, Sales_Category!$A:$A, "<="&$B$5), 0) | G11: =IFERROR(F11-E11, 0) | H11: =IF(AND(F11<>"", E11<>""), IF(F11<=E11*1.05, "OK", IF(F11<=E11*1.15, "WARNING", "OFF")), "")
A12: NA Beverage | B12: =IFERROR(SUMIFS(Sales_Category!$D:$D, Sales_Category!$A:$A, ">="&$B$4, Sales_Category!$A:$A, "<="&$B$5, Sales_Category!$B:$B, "NA Beverage"), 0) | C12: =IFERROR(SUMIFS(Sales_Category!$D:$D, Sales_Category!$A:$A, ">="&($B$4-7), Sales_Category!$A:$A, "<="&($B$5-7), Sales_Category!$B:$B, "NA Beverage"), 0) | D12: =IFERROR(SUMIFS(Sales_Category!$D:$D, Sales_Category!$A:$A, ">="&IF(ISNUMBER($B$4), (IF(ISNUMBER($B$4),DATE(YEAR($B$4-WEEKDAY($B$4,2)+4)-1,1,4)-WEEKDAY(DATE(YEAR($B$4-WEEKDAY($B$4,2)+4)-1,1,4),2)+1+7*(WEEKNUM($B$4-WEEKDAY($B$4,2)+4,2)-1),"")), ""), Sales_Category!$A:$A, "<="&IF(ISNUMBER($B$5), (IF(ISNUMBER($B$5),DATE(YEAR($B$5-WEEKDAY($B$5,2)+4)-1,1,4)-WEEKDAY(DATE(YEAR($B$5-WEEKDAY($B$5,2)+4)-1,1,4),2)+1+7*(WEEKNUM($B$5-WEEKDAY($B$5,2)+4,2)-1)+6,"")), ""), Sales_Category!$B:$B, "NA Beverage"), 0) | E12: 0 | F12: =IFERROR(B12/SUMIFS(Sales_Category!$D:$D, Sales_Category!$A:$A, ">="&$B$4, Sales_Category!$A:$A, "<="&$B$5), 0) | G12: =IFERROR(F12-E12, 0) | H12: =IF(AND(F12<>"", E12<>""), IF(F12<=E12*1.05, "OK", IF(F12<=E12*1.15, "WARNING", "OFF")), "")
A13: Retail | B13: =IFERROR(SUMIFS(Sales_Category!$D:$D, Sales_Category!$A:$A, ">="&$B$4, Sales_Category!$A:$A, "<="&$B$5, Sales_Category!$B:$B, "Retail"), 0) | C13: =IFERROR(SUMIFS(Sales_Category!$D:$D, Sales_Category!$A:$A, ">="&($B$4-7), Sales_Category!$A:$A, "<="&($B$5-7), Sales_Category!$B:$B, "Retail"), 0) | D13: =IFERROR(SUMIFS(Sales_Category!$D:$D, Sales_Category!$A:$A, ">="&IF(ISNUMBER($B$4), (IF(ISNUMBER($B$4),DATE(YEAR($B$4-WEEKDAY($B$4,2)+4)-1,1,4)-WEEKDAY(DATE(YEAR($B$4-WEEKDAY($B$4,2)+4)-1,1,4),2)+1+7*(WEEKNUM($B$4-WEEKDAY($B$4,2)+4,2)-1),"")), ""), Sales_Category!$A:$A, "<="&IF(ISNUMBER($B$5), (IF(ISNUMBER($B$5),DATE(YEAR($B$5-WEEKDAY($B$5,2)+4)-1,1,4)-WEEKDAY(DATE(YEAR($B$5-WEEKDAY($B$5,2)+4)-1,1,4),2)+1+7*(WEEKNUM($B$5-WEEKDAY($B$5,2)+4,2)-1)+6,"")), ""), Sales_Category!$B:$B, "Retail"), 0) | E13: 0 | F13: =IFERROR(B13/SUMIFS(Sales_Category!$D:$D, Sales_Category!$A:$A, ">="&$B$4, Sales_Category!$A:$A, "<="&$B$5), 0) | G13: =IFERROR(F13-E13, 0) | H13: =IF(AND(F13<>"", E13<>""), IF(F13<=E13*1.05, "OK", IF(F13<=E13*1.15, "WARNING", "OFF")), "")
A14: Non-Grat Service Charges | B14: =IFERROR(SUMIFS(Sales_Category!$D:$D, Sales_Category!$A:$A, ">="&$B$4, Sales_Category!$A:$A, "<="&$B$5, Sales_Category!$B:$B, "Non-Grat Svc Charges"), 0) | C14: =IFERROR(SUMIFS(Sales_Category!$D:$D, Sales_Category!$A:$A, ">="&($B$4-7), Sales_Category!$A:$A, "<="&($B$5-7), Sales_Category!$B:$B, "Non-Grat Svc Charges"), 0) | D14: =IFERROR(SUMIFS(Sales_Category!$D:$D, Sales_Category!$A:$A, ">="&IF(ISNUMBER($B$4), (IF(ISNUMBER($B$4),DATE(YEAR($B$4-WEEKDAY($B$4,2)+4)-1,1,4)-WEEKDAY(DATE(YEAR($B$4-WEEKDAY($B$4,2)+4)-1,1,4),2)+1+7*(WEEKNUM($B$4-WEEKDAY($B$4,2)+4,2)-1),"")), ""), Sales_Category!$A:$A, "<="&IF(ISNUMBER($B$5), (IF(ISNUMBER($B$5),DATE(YEAR($B$5-WEEKDAY($B$5,2)+4)-1,1,4)-WEEKDAY(DATE(YEAR($B$5-WEEKDAY($B$5,2)+4)-1,1,4),2)+1+7*(WEEKNUM($B$5-WEEKDAY($B$5,2)+4,2)-1)+6,"")), ""), Sales_Category!$B:$B, "Non-Grat Svc Charges"), 0) | E14: 0 | F14: =IFERROR(B14/SUMIFS(Sales_Category!$D:$D, Sales_Category!$A:$A, ">="&$B$4, Sales_Category!$A:$A, "<="&$B$5), 0) | G14: =IFERROR(F14-E14, 0) | H14: =IF(AND(F14<>"", E14<>""), IF(F14<=E14*1.05, "OK", IF(F14<=E14*1.15, "WARNING", "OFF")), "")
A15: Custom Amounts | B15: =IFERROR(SUMIFS(Sales_Category!$D:$D, Sales_Category!$A:$A, ">="&$B$4, Sales_Category!$A:$A, "<="&$B$5, Sales_Category!$B:$B, "Custom Amounts"), 0) | C15: =IFERROR(SUMIFS(Sales_Category!$D:$D, Sales_Category!$A:$A, ">="&($B$4-7), Sales_Category!$A:$A, "<="&($B$5-7), Sales_Category!$B:$B, "Custom Amounts"), 0) | D15: =IFERROR(SUMIFS(Sales_Category!$D:$D, Sales_Category!$A:$A, ">="&IF(ISNUMBER($B$4), (IF(ISNUMBER($B$4),DATE(YEAR($B$4-WEEKDAY($B$4,2)+4)-1,1,4)-WEEKDAY(DATE(YEAR($B$4-WEEKDAY($B$4,2)+4)-1,1,4),2)+1+7*(WEEKNUM($B$4-WEEKDAY($B$4,2)+4,2)-1),"")), ""), Sales_Category!$A:$A, "<="&IF(ISNUMBER($B$5), (IF(ISNUMBER($B$5),DATE(YEAR($B$5-WEEKDAY($B$5,2)+4)-1,1,4)-WEEKDAY(DATE(YEAR($B$5-WEEKDAY($B$5,2)+4)-1,1,4),2)+1+7*(WEEKNUM($B$5-WEEKDAY($B$5,2)+4,2)-1)+6,"")), ""), Sales_Category!$B:$B, "Custom Amounts"), 0) | E15: 0 | F15: =IFERROR(B15/SUMIFS(Sales_Category!$D:$D, Sales_Category!$A:$A, ">="&$B$4, Sales_Category!$A:$A, "<="&$B$5), 0) | G15: =IFERROR(F15-E15, 0) | H15: =IF(AND(F15<>"", E15<>""), IF(F15<=E15*1.05, "OK", IF(F15<=E15*1.15, "WARNING", "OFF")), "")
A16: Uncategorized | B16: =IFERROR(SUMIFS(Sales_Category!$D:$D, Sales_Category!$A:$A, ">="&$B$4, Sales_Category!$A:$A, "<="&$B$5, Sales_Category!$B:$B, "No Sales Category Assigned"), 0) | C16: =IFERROR(SUMIFS(Sales_Category!$D:$D, Sales_Category!$A:$A, ">="&($B$4-7), Sales_Category!$A:$A, "<="&($B$5-7), Sales_Category!$B:$B, "No Sales Category Assigned"), 0) | D16: =IFERROR(SUMIFS(Sales_Category!$D:$D, Sales_Category!$A:$A, ">="&IF(ISNUMBER($B$4), (IF(ISNUMBER($B$4),DATE(YEAR($B$4-WEEKDAY($B$4,2)+4)-1,1,4)-WEEKDAY(DATE(YEAR($B$4-WEEKDAY($B$4,2)+4)-1,1,4),2)+1+7*(WEEKNUM($B$4-WEEKDAY($B$4,2)+4,2)-1),"")), ""), Sales_Category!$A:$A, "<="&IF(ISNUMBER($B$5), (IF(ISNUMBER($B$5),DATE(YEAR($B$5-WEEKDAY($B$5,2)+4)-1,1,4)-WEEKDAY(DATE(YEAR($B$5-WEEKDAY($B$5,2)+4)-1,1,4),2)+1+7*(WEEKNUM($B$5-WEEKDAY($B$5,2)+4,2)-1)+6,"")), ""), Sales_Category!$B:$B, "No Sales Category Assigned"), 0) | E16: 0 | F16: =IFERROR(B16/SUMIFS(Sales_Category!$D:$D, Sales_Category!$A:$A, ">="&$B$4, Sales_Category!$A:$A, "<="&$B$5), 0) | G16: =IFERROR(F16-E16, 0) | H16: =IF(AND(F16<>"", E16<>""), IF(F16<=E16*1.05, "OK", IF(F16<=E16*1.15, "WARNING", "OFF")), "")
A17: Total | B17: =SUM(B9:B16) | C17: =SUM(C9:C16) | D17: =SUM(D9:D16) | E17: =SUM(E9:E16) | F17: =SUM(F9:F16) | G17: =SUM(G9:G16)
A19: COST OF GOODS SOLD
A20: Category | B20: This Week | C20: Last Week | D20: Last Year | E20: Target % | F20: Actual % | G20: Status
A21: Food Cost | B21: =IFERROR(SUMIFS(COGS_Input!$G:$G, COGS_Input!$A:$A, ">="&$B$4, COGS_Input!$A:$A, "<="&$B$5, COGS_Input!$B:$B, "Food + NA Beverage"), 0) | C21: =IFERROR(SUMIFS(COGS_Input!$G:$G, COGS_Input!$A:$A, ">="&($B$4-7), COGS_Input!$A:$A, "<="&($B$5-7), COGS_Input!$B:$B, "Food + NA Beverage"), 0) | D21: =IFERROR(SUMIFS(COGS_Input!$G:$G, COGS_Input!$A:$A, ">="&IF(ISNUMBER($B$4), (IF(ISNUMBER($B$4),DATE(YEAR($B$4-WEEKDAY($B$4,2)+4)-1,1,4)-WEEKDAY(DATE(YEAR($B$4-WEEKDAY($B$4,2)+4)-1,1,4),2)+1+7*(WEEKNUM($B$4-WEEKDAY($B$4,2)+4,2)-1),"")), ""), COGS_Input!$A:$A, "<="&IF(ISNUMBER($B$5), (IF(ISNUMBER($B$5),DATE(YEAR($B$5-WEEKDAY($B$5,2)+4)-1,1,4)-WEEKDAY(DATE(YEAR($B$5-WEEKDAY($B$5,2)+4)-1,1,4),2)+1+7*(WEEKNUM($B$5-WEEKDAY($B$5,2)+4,2)-1)+6,"")), ""), COGS_Input!$B:$B, "Food + NA Beverage"), 0) | E21: 0.25 | F21: =IFERROR(B21/SUMIFS(Sales_Category!$D:$D, Sales_Category!$A:$A, ">="&$B$4, Sales_Category!$A:$A, "<="&$B$5, Sales_Category!$B:$B, "Food"), 0) | G21: =IF(AND(F21<>"", E21<>""), IF(F21<=E21*1.05, "OK", IF(F21<=E21*1.15, "WARNING", "OFF")), "")
A22: Liquor Cost | B22: =IFERROR(SUMIFS(COGS_Input!$G:$G, COGS_Input!$A:$A, ">="&$B$4, COGS_Input!$A:$A, "<="&$B$5, COGS_Input!$B:$B, "Liquor + Wine"), 0) | C22: =IFERROR(SUMIFS(COGS_Input!$G:$G, COGS_Input!$A:$A, ">="&($B$4-7), COGS_Input!$A:$A, "<="&($B$5-7), COGS_Input!$B:$B, "Liquor + Wine"), 0) | D22: =IFERROR(SUMIFS(COGS_Input!$G:$G, COGS_Input!$A:$A, ">="&IF(ISNUMBER($B$4), (IF(ISNUMBER($B$4),DATE(YEAR($B$4-WEEKDAY($B$4,2)+4)-1,1,4)-WEEKDAY(DATE(YEAR($B$4-WEEKDAY($B$4,2)+4)-1,1,4),2)+1+7*(WEEKNUM($B$4-WEEKDAY($B$4,2)+4,2)-1),"")), ""), COGS_Input!$A:$A, "<="&IF(ISNUMBER($B$5), (IF(ISNUMBER($B$5),DATE(YEAR($B$5-WEEKDAY($B$5,2)+4)-1,1,4)-WEEKDAY(DATE(YEAR($B$5-WEEKDAY($B$5,2)+4)-1,1,4),2)+1+7*(WEEKNUM($B$5-WEEKDAY($B$5,2)+4,2)-1)+6,"")), ""), COGS_Input!$B:$B, "Liquor + Wine"), 0) | E22: 0.12 | F22: =IFERROR(B22/SUMIFS(Sales_Category!$D:$D, Sales_Category!$A:$A, ">="&$B$4, Sales_Category!$A:$A, "<="&$B$5, Sales_Category!$B:$B, "Liquor"), 0) | G22: =IF(AND(F22<>"", E22<>""), IF(F22<=E22*1.05, "OK", IF(F22<=E22*1.15, "WARNING", "OFF")), "")
A23: Beer Cost | B23: =IFERROR(SUMIFS(COGS_Input!$G:$G, COGS_Input!$A:$A, ">="&$B$4, COGS_Input!$A:$A, "<="&$B$5, COGS_Input!$B:$B, "Beer"), 0) | C23: =IFERROR(SUMIFS(COGS_Input!$G:$G, COGS_Input!$A:$A, ">="&($B$4-7), COGS_Input!$A:$A, "<="&($B$5-7), COGS_Input!$B:$B, "Beer"), 0) | D23: =IFERROR(SUMIFS(COGS_Input!$G:$G, COGS_Input!$A:$A, ">="&IF(ISNUMBER($B$4), (IF(ISNUMBER($B$4),DATE(YEAR($B$4-WEEKDAY($B$4,2)+4)-1,1,4)-WEEKDAY(DATE(YEAR($B$4-WEEKDAY($B$4,2)+4)-1,1,4),2)+1+7*(WEEKNUM($B$4-WEEKDAY($B$4,2)+4,2)-1),"")), ""), COGS_Input!$A:$A, "<="&IF(ISNUMBER($B$5), (IF(ISNUMBER($B$5),DATE(YEAR($B$5-WEEKDAY($B$5,2)+4)-1,1,4)-WEEKDAY(DATE(YEAR($B$5-WEEKDAY($B$5,2)+4)-1,1,4),2)+1+7*(WEEKNUM($B$5-WEEKDAY($B$5,2)+4,2)-1)+6,"")), ""), COGS_Input!$B:$B, "Beer"), 0) | E23: 0.15 | F23: =IFERROR(B23/SUMIFS(Sales_Category!$D:$D, Sales_Category!$A:$A, ">="&$B$4, Sales_Category!$A:$A, "<="&$B$5, Sales_Category!$B:$B, "Bottled Beer"), 0) | G23: =IF(AND(F23<>"", E23<>""), IF(F23<=E23*1.05, "OK", IF(F23<=E23*1.15, "WARNING", "OFF")), "")
A24: Retail Cost | B24: =IFERROR(SUMIFS(COGS_Input!$G:$G, COGS_Input!$A:$A, ">="&$B$4, COGS_Input!$A:$A, "<="&$B$5, COGS_Input!$B:$B, "Retail"), 0) | C24: =IFERROR(SUMIFS(COGS_Input!$G:$G, COGS_Input!$A:$A, ">="&($B$4-7), COGS_Input!$A:$A, "<="&($B$5-7), COGS_Input!$B:$B, "Retail"), 0) | D24: =IFERROR(SUMIFS(COGS_Input!$G:$G, COGS_Input!$A:$A, ">="&IF(ISNUMBER($B$4), (IF(ISNUMBER($B$4),DATE(YEAR($B$4-WEEKDAY($B$4,2)+4)-1,1,4)-WEEKDAY(DATE(YEAR($B$4-WEEKDAY($B$4,2)+4)-1,1,4),2)+1+7*(WEEKNUM($B$4-WEEKDAY($B$4,2)+4,2)-1),"")), ""), COGS_Input!$A:$A, "<="&IF(ISNUMBER($B$5), (IF(ISNUMBER($B$5),DATE(YEAR($B$5-WEEKDAY($B$5,2)+4)-1,1,4)-WEEKDAY(DATE(YEAR($B$5-WEEKDAY($B$5,2)+4)-1,1,4),2)+1+7*(WEEKNUM($B$5-WEEKDAY($B$5,2)+4,2)-1)+6,"")), ""), COGS_Input!$B:$B, "Retail"), 0) | E24: 0 | F24: =IFERROR(B24/SUMIFS(Sales_Category!$D:$D, Sales_Category!$A:$A, ">="&$B$4, Sales_Category!$A:$A, "<="&$B$5, Sales_Category!$B:$B, "Retail"), 0) | G24: =IF(AND(F24<>"", E24<>""), IF(F24<=E24*1.05, "OK", IF(F24<=E24*1.15, "WARNING", "OFF")), "")
A25: Total COGS | B25: =IFERROR(SUMIFS(COGS_Input!$G:$G, COGS_Input!$A:$A, ">="&$B$4, COGS_Input!$A:$A, "<="&$B$5), 0) | C25: =IFERROR(SUMIFS(COGS_Input!$G:$G, COGS_Input!$A:$A, ">="&($B$4-7), COGS_Input!$A:$A, "<="&($B$5-7)), 0) | D25: =IFERROR(SUMIFS(COGS_Input!$G:$G, COGS_Input!$A:$A, ">="&IF(ISNUMBER($B$4), (IF(ISNUMBER($B$4),DATE(YEAR($B$4-WEEKDAY($B$4,2)+4)-1,1,4)-WEEKDAY(DATE(YEAR($B$4-WEEKDAY($B$4,2)+4)-1,1,4),2)+1+7*(WEEKNUM($B$4-WEEKDAY($B$4,2)+4,2)-1),"")), ""), COGS_Input!$A:$A, "<="&IF(ISNUMBER($B$5), (IF(ISNUMBER($B$5),DATE(YEAR($B$5-WEEKDAY($B$5,2)+4)-1,1,4)-WEEKDAY(DATE(YEAR($B$5-WEEKDAY($B$5,2)+4)-1,1,4),2)+1+7*(WEEKNUM($B$5-WEEKDAY($B$5,2)+4,2)-1)+6,"")), "")), 0) | E25: 0.15 | F25: =IFERROR(B25/SUMIFS(Sales_Category!$D:$D, Sales_Category!$A:$A, ">="&$B$4, Sales_Category!$A:$A, "<="&$B$5), 0) | G25: =IF(AND(F25<>"", E25<>""), IF(F25<=E25*1.05, "OK", IF(F25<=E25*1.15, "WARNING", "OFF")), "")
A28: LABOR COST
A29: Category | B29: This Week | C29: Last Week | D29: Last Year | E29: Target % | F29: Actual % | G29: Status
A30: FOH Labor | B30: =IFERROR(SUMIFS(Labor_Input!$J:$J, Labor_Input!$A:$A, ">="&$B$4, Labor_Input!$A:$A, "<="&$B$5, Labor_Input!$D:$D, "FOH"), 0) | C30: =IFERROR(SUMIFS(Labor_Input!$J:$J, Labor_Input!$A:$A, ">="&($B$4-7), Labor_Input!$A:$A, "<="&($B$5-7), Labor_Input!$D:$D, "FOH"), 0) | D30: =IFERROR(SUMIFS(Labor_Input!$J:$J, Labor_Input!$A:$A, ">="&(IF(ISNUMBER($B$4),DATE(YEAR($B$4-WEEKDAY($B$4,2)+4)-1,1,4)-WEEKDAY(DATE(YEAR($B$4-WEEKDAY($B$4,2)+4)-1,1,4),2)+1+7*(WEEKNUM($B$4-WEEKDAY($B$4,2)+4,2)-1),"")), Labor_Input!$A:$A, "<="&(IF(ISNUMBER($B$5),DATE(YEAR($B$5-WEEKDAY($B$5,2)+4)-1,1,4)-WEEKDAY(DATE(YEAR($B$5-WEEKDAY($B$5,2)+4)-1,1,4),2)+1+7*(WEEKNUM($B$5-WEEKDAY($B$5,2)+4,2)-1)+6,"")), Labor_Input!$D:$D, "FOH"), 0) | E30: 0.1 | G30: =IF(AND(F30<>"", E30<>""), IF(F30<=E30*1.05, "OK", IF(F30<=E30*1.15, "WARNING", "OFF")), "")
A31: BOH Labor | B31: =IFERROR(SUMIFS(Labor_Input!$J:$J, Labor_Input!$A:$A, ">="&$B$4, Labor_Input!$A:$A, "<="&$B$5, Labor_Input!$D:$D, "BOH"), 0) | C31: =IFERROR(SUMIFS(Labor_Input!$J:$J, Labor_Input!$A:$A, ">="&($B$4-7), Labor_Input!$A:$A, "<="&($B$5-7), Labor_Input!$D:$D, "BOH"), 0) | D31: =IFERROR(SUMIFS(Labor_Input!$J:$J, Labor_Input!$A:$A, ">="&(IF(ISNUMBER($B$4),DATE(YEAR($B$4-WEEKDAY($B$4,2)+4)-1,1,4)-WEEKDAY(DATE(YEAR($B$4-WEEKDAY($B$4,2)+4)-1,1,4),2)+1+7*(WEEKNUM($B$4-WEEKDAY($B$4,2)+4,2)-1),"")), Labor_Input!$A:$A, "<="&(IF(ISNUMBER($B$5),DATE(YEAR($B$5-WEEKDAY($B$5,2)+4)-1,1,4)-WEEKDAY(DATE(YEAR($B$5-WEEKDAY($B$5,2)+4)-1,1,4),2)+1+7*(WEEKNUM($B$5-WEEKDAY($B$5,2)+4,2)-1)+6,"")), Labor_Input!$D:$D, "BOH"), 0) | E31: 0.1 | G31: =IF(AND(F31<>"", E31<>""), IF(F31<=E31*1.05, "OK", IF(F31<=E31*1.15, "WARNING", "OFF")), "")
A32: Management | B32: =IFERROR(SUMIFS(Labor_Input!$J:$J, Labor_Input!$A:$A, ">="&$B$4, Labor_Input!$A:$A, "<="&$B$5, Labor_Input!$D:$D, "Management"), 0) | C32: =IFERROR(SUMIFS(Labor_Input!$J:$J, Labor_Input!$A:$A, ">="&($B$4-7), Labor_Input!$A:$A, "<="&($B$5-7), Labor_Input!$D:$D, "Management"), 0) | D32: =IFERROR(SUMIFS(Labor_Input!$J:$J, Labor_Input!$A:$A, ">="&(IF(ISNUMBER($B$4),DATE(YEAR($B$4-WEEKDAY($B$4,2)+4)-1,1,4)-WEEKDAY(DATE(YEAR($B$4-WEEKDAY($B$4,2)+4)-1,1,4),2)+1+7*(WEEKNUM($B$4-WEEKDAY($B$4,2)+4,2)-1),"")), Labor_Input!$A:$A, "<="&(IF(ISNUMBER($B$5),DATE(YEAR($B$5-WEEKDAY($B$5,2)+4)-1,1,4)-WEEKDAY(DATE(YEAR($B$5-WEEKDAY($B$5,2)+4)-1,1,4),2)+1+7*(WEEKNUM($B$5-WEEKDAY($B$5,2)+4,2)-1)+6,"")), Labor_Input!$D:$D, "Management"), 0) | E32: 0.1 | G32: =IF(AND(F32<>"", E32<>""), IF(F32<=E32*1.05, "OK", IF(F32<=E32*1.15, "WARNING", "OFF")), "")
A33: Security | B33: =IFERROR(SUMIFS(Labor_Input!$J:$J, Labor_Input!$A:$A, ">="&$B$4, Labor_Input!$A:$A, "<="&$B$5, Labor_Input!$D:$D, "Security"), 0) | C33: =IFERROR(SUMIFS(Labor_Input!$J:$J, Labor_Input!$A:$A, ">="&($B$4-7), Labor_Input!$A:$A, "<="&($B$5-7), Labor_Input!$D:$D, "Security"), 0) | D33: =IFERROR(SUMIFS(Labor_Input!$J:$J, Labor_Input!$A:$A, ">="&(IF(ISNUMBER($B$4),DATE(YEAR($B$4-WEEKDAY($B$4,2)+4)-1,1,4)-WEEKDAY(DATE(YEAR($B$4-WEEKDAY($B$4,2)+4)-1,1,4),2)+1+7*(WEEKNUM($B$4-WEEKDAY($B$4,2)+4,2)-1),"")), Labor_Input!$A:$A, "<="&(IF(ISNUMBER($B$5),DATE(YEAR($B$5-WEEKDAY($B$5,2)+4)-1,1,4)-WEEKDAY(DATE(YEAR($B$5-WEEKDAY($B$5,2)+4)-1,1,4),2)+1+7*(WEEKNUM($B$5-WEEKDAY($B$5,2)+4,2)-1)+6,"")), Labor_Input!$D:$D, "Security"), 0) | E33: 0 | G33: =IF(AND(F33<>"", E33<>""), IF(F33<=E33*1.05, "OK", IF(F33<=E33*1.15, "WARNING", "OFF")), "")
A34: Labor Tax | B34: =IFERROR((SUMIFS(Labor_Input!$J:$J, Labor_Input!$A:$A, ">="&$B$4, Labor_Input!$A:$A, "<="&$B$5, Labor_Input!$D:$D, "FOH") + SUMIFS(Labor_Input!$J:$J, Labor_Input!$A:$A, ">="&$B$4, Labor_Input!$A:$A, "<="&$B$5, Labor_Input!$D:$D, "BOH") + SUMIFS(Labor_Input!$J:$J, Labor_Input!$A:$A, ">="&$B$4, Labor_Input!$A:$A, "<="&$B$5, Labor_Input!$D:$D, "Management")) * 0.15, 0) | C34: =IFERROR((SUMIFS(Labor_Input!$J:$J, Labor_Input!$A:$A, ">="&($B$4-7), Labor_Input!$A:$A, "<="&($B$5-7), Labor_Input!$D:$D, "FOH") + SUMIFS(Labor_Input!$J:$J, Labor_Input!$A:$A, ">="&($B$4-7), Labor_Input!$A:$A, "<="&($B$5-7), Labor_Input!$D:$D, "BOH") + SUMIFS(Labor_Input!$J:$J, Labor_Input!$A:$A, ">="&($B$4-7), Labor_Input!$A:$A, "<="&($B$5-7), Labor_Input!$D:$D, "Management")) * 0.15, 0) | D34: =IFERROR((SUMIFS(Labor_Input!$J:$J, Labor_Input!$A:$A, ">="&(IF(ISNUMBER($B$4),DATE(YEAR($B$4-WEEKDAY($B$4,2)+4)-1,1,4)-WEEKDAY(DATE(YEAR($B$4-WEEKDAY($B$4,2)+4)-1,1,4),2)+1+7*(WEEKNUM($B$4-WEEKDAY($B$4,2)+4,2)-1),"")), Labor_Input!$A:$A, "<="&(IF(ISNUMBER($B$5),DATE(YEAR($B$5-WEEKDAY($B$5,2)+4)-1,1,4)-WEEKDAY(DATE(YEAR($B$5-WEEKDAY($B$5,2)+4)-1,1,4),2)+1+7*(WEEKNUM($B$5-WEEKDAY($B$5,2)+4,2)-1)+6,"")), Labor_Input!$D:$D, "FOH") + SUMIFS(Labor_Input!$J:$J, Labor_Input!$A:$A, ">="&(IF(ISNUMBER($B$4),DATE(YEAR($B$4-WEEKDAY($B$4,2)+4)-1,1,4)-WEEKDAY(DATE(YEAR($B$4-WEEKDAY($B$4,2)+4)-1,1,4),2)+1+7*(WEEKNUM($B$4-WEEKDAY($B$4,2)+4,2)-1),"")), Labor_Input!$A:$A, "<="&(IF(ISNUMBER($B$5),DATE(YEAR($B$5-WEEKDAY($B$5,2)+4)-1,1,4)-WEEKDAY(DATE(YEAR($B$5-WEEKDAY($B$5,2)+4)-1,1,4),2)+1+7*(WEEKNUM($B$5-WEEKDAY($B$5,2)+4,2)-1)+6,"")), Labor_Input!$D:$D, "BOH") + SUMIFS(Labor_Input!$J:$J, Labor_Input!$A:$A, ">="&(IF(ISNUMBER($B$4),DATE(YEAR($B$4-WEEKDAY($B$4,2)+4)-1,1,4)-WEEKDAY(DATE(YEAR($B$4-WEEKDAY($B$4,2)+4)-1,1,4),2)+1+7*(WEEKNUM($B$4-WEEKDAY($B$4,2)+4,2)-1),"")), Labor_Input!$A:$A, "<="&(IF(ISNUMBER($B$5),DATE(YEAR($B$5-WEEKDAY($B$5,2)+4)-1,1,4)-WEEKDAY(DATE(YEAR($B$5-WEEKDAY($B$5,2)+4)-1,1,4),2)+1+7*(WEEKNUM($B$5-WEEKDAY($B$5,2)+4,2)-1)+6,"")), Labor_Input!$D:$D, "Management")) * 0.15, 0) | E34: 0 | G34: =IF(AND(F34<>"", E34<>""), IF(F34<=E34*1.05, "OK", IF(F34<=E34*1.15, "WARNING", "OFF")), "")
A35: Compensation | B35: =IFERROR(SUMIFS(Labor_Input!$J:$J, Labor_Input!$A:$A, ">="&$B$4, Labor_Input!$A:$A, "<="&$B$5, Labor_Input!$D:$D, "Other"), 0) | C35: =IFERROR(SUMIFS(Labor_Input!$J:$J, Labor_Input!$A:$A, ">="&($B$4-7), Labor_Input!$A:$A, "<="&($B$5-7), Labor_Input!$D:$D, "Other"), 0) | D35: =IFERROR(SUMIFS(Labor_Input!$J:$J, Labor_Input!$A:$A, ">="&(IF(ISNUMBER($B$4),DATE(YEAR($B$4-WEEKDAY($B$4,2)+4)-1,1,4)-WEEKDAY(DATE(YEAR($B$4-WEEKDAY($B$4,2)+4)-1,1,4),2)+1+7*(WEEKNUM($B$4-WEEKDAY($B$4,2)+4,2)-1),"")), Labor_Input!$A:$A, "<="&(IF(ISNUMBER($B$5),DATE(YEAR($B$5-WEEKDAY($B$5,2)+4)-1,1,4)-WEEKDAY(DATE(YEAR($B$5-WEEKDAY($B$5,2)+4)-1,1,4),2)+1+7*(WEEKNUM($B$5-WEEKDAY($B$5,2)+4,2)-1)+6,"")), Labor_Input!$D:$D, "Other"), 0) | E35: 0 | G35: =IF(AND(F35<>"", E35<>""), IF(F35<=E35*1.05, "OK", IF(F35<=E35*1.15, "WARNING", "OFF")), "")
A36: Other | B36: =IFERROR(SUMIFS(Labor_Input!$J:$J, Labor_Input!$A:$A, ">="&$B$4, Labor_Input!$A:$A, "<="&$B$5, Labor_Input!$D:$D, "Other"), 0) | C36: =IFERROR(SUMIFS(Labor_Input!$J:$J, Labor_Input!$A:$A, ">="&($B$4-7), Labor_Input!$A:$A, "<="&($B$5-7), Labor_Input!$D:$D, "Other"), 0) | D36: =IFERROR(SUMIFS(Labor_Input!$J:$J, Labor_Input!$A:$A, ">="&(IF(ISNUMBER($B$4),DATE(YEAR($B$4-WEEKDAY($B$4,2)+4)-1,1,4)-WEEKDAY(DATE(YEAR($B$4-WEEKDAY($B$4,2)+4)-1,1,4),2)+1+7*(WEEKNUM($B$4-WEEKDAY($B$4,2)+4,2)-1),"")), Labor_Input!$A:$A, "<="&(IF(ISNUMBER($B$5),DATE(YEAR($B$5-WEEKDAY($B$5,2)+4)-1,1,4)-WEEKDAY(DATE(YEAR($B$5-WEEKDAY($B$5,2)+4)-1,1,4),2)+1+7*(WEEKNUM($B$5-WEEKDAY($B$5,2)+4,2)-1)+6,"")), Labor_Input!$D:$D, "Other"), 0) | E36: 0 | G36: =IF(AND(F36<>"", E36<>""), IF(F36<=E36*1.05, "OK", IF(F36<=E36*1.15, "WARNING", "OFF")), "")
A37: Total Labor | B37: =IFERROR(SUMIFS(Labor_Input!$J:$J, Labor_Input!$A:$A, ">="&$B$4, Labor_Input!$A:$A, "<="&$B$5), 0) | C37: =IFERROR(SUMIFS(Labor_Input!$J:$J, Labor_Input!$A:$A, ">="&($B$4-7), Labor_Input!$A:$A, "<="&($B$5-7)), 0) | D37: =IFERROR(SUMIFS(Labor_Input!$J:$J, Labor_Input!$A:$A, ">="&(IF(ISNUMBER($B$4),DATE(YEAR($B$4-WEEKDAY($B$4,2)+4)-1,1,4)-WEEKDAY(DATE(YEAR($B$4-WEEKDAY($B$4,2)+4)-1,1,4),2)+1+7*(WEEKNUM($B$4-WEEKDAY($B$4,2)+4,2)-1),"")), Labor_Input!$A:$A, "<="&(IF(ISNUMBER($B$5),DATE(YEAR($B$5-WEEKDAY($B$5,2)+4)-1,1,4)-WEEKDAY(DATE(YEAR($B$5-WEEKDAY($B$5,2)+4)-1,1,4),2)+1+7*(WEEKNUM($B$5-WEEKDAY($B$5,2)+4,2)-1)+6,""))), 0) | E37: 0.25 | F37: =IFERROR(B37/SUMIFS(Sales_Category!$D:$D, Sales_Category!$A:$A, ">="&$B$4, Sales_Category!$A:$A, "<="&$B$5), 0) | G37: =IF(AND(F37<>"", E37<>""), IF(F37<=E37*1.05, "OK", IF(F37<=E37*1.15, "WARNING", "OFF")), "")
A40: PRIME COST
A41: Metric | B41: This Week | C41: Target % | D41: Actual % | E41: Status
A42: Prime Cost % | B42: =IFERROR(SUMIFS(COGS_Input!$G:$G, COGS_Input!$A:$A, ">="&$B$4, COGS_Input!$A:$A, "<="&$B$5) + SUMIFS(Labor_Input!$J:$J, Labor_Input!$A:$A, ">="&$B$4, Labor_Input!$A:$A, "<="&$B$5), 0) | C42: 0.45 | D42: =IFERROR(B42/SUMIFS(Sales_Category!$D:$D, Sales_Category!$A:$A, ">="&$B$4, Sales_Category!$A:$A, "<="&$B$5), 0) | E42: =IF(AND(D42<>"", C42<>""), IF(D42<=C42*1.05, "OK", IF(D42<=C42*1.15, "WARNING", "OFF")), "")
A45: SUMMARY METRICS
A46: Net Sales | B46: =SUMIFS(Sales_Category!$D:$D, Sales_Category!$A:$A, ">="&$B$4, Sales_Category!$A:$A, "<="&$B$5)
A47: Gross Sales | B47: =SUMIFS(Sales_Category!$G:$G, Sales_Category!$A:$A, ">="&$B$4, Sales_Category!$A:$A, "<="&$B$5)
A48: Total Discounts | B48: =SUMIFS(Sales_Category!$E:$E, Sales_Category!$A:$A, ">="&$B$4, Sales_Category!$A:$A, "<="&$B$5)
...

Sheet Sales_Payments
A1: Date | B1: Payment type | C1: Payment sub type | D1: Count | E1: Amount | F1: Tips | G1: Grat | H1: Tax amount | I1: Refunds | J1: Tip refunds | K1: Legacy tips | L1: Total | M1: Tips/Grat %
A2: 46032 | B2: Cash | D2: 22 | E2: 1031.7 | F2: 0 | G2: 64.63 | H2: 179.85 | I2: 0 | J2: 0 | K2: 0 | L2: 1096.33 | M2: 7.6
A3: 46032 | B3: Credit/debit | D3: 161 | E3: 6126.7 | F3: 504.41 | G3: 781.7 | H3: 964.16 | I3: 0 | J3: 0 | K3: 504.41 | L3: 7412.81 | M3: 24.8
A4: 46032 | B4: Credit/debit | C4: AMEX | D4: 7 | E4: 301.45 | F4: 37.08 | G4: 41.58 | H4: 49.28 | I4: 0 | J4: 0 | K4: 37.08 | L4: 380.11 | M4: 31
A5: 46032 | B5: Credit/debit | C5: DISCOVER | D5: 3 | E5: 68.83 | F5: 4.2 | G5: 7.43 | H5: 7.89 | I5: 0 | J5: 0 | K5: 4.2 | L5: 80.46 | M5: 19.1
A6: 46032 | B6: Credit/debit | C6: MASTERCARD | D6: 44 | E6: 1713.36 | F6: 68.08 | G6: 242.97 | H6: 264.3 | I6: 0 | J6: 0 | K6: 68.08 | L6: 2024.41 | M6: 21.5
A7: 46032 | B7: Credit/debit | C7: VISA | D7: 107 | E7: 4043.06 | F7: 395.05 | G7: 489.72 | H7: 642.69 | I7: 0 | J7: 0 | K7: 395.05 | L7: 4927.83 | M7: 25.9
A8: 46032 | B8: Gift Card | D8: 0 | E8: 0 | F8: 0 | G8: 0 | H8: 0 | I8: 0 | J8: 0 | K8: 0 | L8: 0
A9: 46032 | B9: Other | D9: 2 | E9: 134.68 | F9: 10 | G9: 4 | H9: 19.73 | I9: 0 | J9: 0 | K9: 10 | L9: 148.68 | M9: 12.2
A10: 46032 | B10: Other | C10: inkind | D10: 2 | E10: 134.68 | F10: 10 | G10: 4 | H10: 19.73 | I10: 0 | J10: 0 | K10: 10 | L10: 148.68 | M10: 12.2
A11: 46031 | B11: Cash | D11: 3 | E11: 290.81 | F11: 0 | G11: 0 | H11: 38.46 | I11: 0 | J11: 0 | K11: 0 | L11: 290.81 | M11: 0
A12: 46031 | B12: Credit/debit | D12: 14 | E12: 733.98 | F12: 44.58 | G12: 89.06 | H12: 97.1 | I12: 0 | J12: 0 | K12: 44.58 | L12: 867.62 | M12: 21
A13: 46031 | B13: Credit/debit | C13: AMEX | D13: 1 | E13: 53.23 | F13: 0 | G13: 7.73 | H13: 8.76 | I13: 0 | J13: 0 | K13: 0 | L13: 60.96 | M13: 17.4
A14: 46031 | B14: Credit/debit | C14: MASTERCARD | D14: 7 | E14: 173.58 | F14: 5.58 | G14: 23.56 | H14: 22.81 | I14: 0 | J14: 0 | K14: 5.58 | L14: 202.72 | M14: 19.3
A15: 46031 | B15: Credit/debit | C15: VISA | D15: 6 | E15: 507.17 | F15: 39 | G15: 57.77 | H15: 65.53 | I15: 0 | J15: 0 | K15: 39 | L15: 603.94 | M15: 21.9
A16: 46031 | B16: Gift Card | D16: 0 | E16: 0 | F16: 0 | G16: 0 | H16: 0 | I16: 0 | J16: 0 | K16: 0 | L16: 0
A17: 46031 | B17: Other | D17: 0 | E17: 0 | F17: 0 | G17: 0 | H17: 0 | I17: 0 | J17: 0 | K17: 0 | L17: 0
A18: 46030 | B18: Cash | D18: 0 | E18: 0 | F18: 0 | G18: 0 | H18: 0 | I18: 0 | J18: 0 | K18: 0 | L18: 0
A19: 46030 | B19: Credit/debit | D19: 1 | E19: 15.53 | F19: 5 | G19: 0 | H19: 2.53 | I19: 0 | J19: 0 | K19: 5 | L19: 20.53 | M19: 38.5
A20: 46030 | B20: Credit/debit | C20: MASTERCARD | D20: 1 | E20: 15.53 | F20: 5 | G20: 0 | H20: 2.53 | I20: 0 | J20: 0 | K20: 5 | L20: 20.53 | M20: 38.5
A21: 46030 | B21: Gift Card | D21: 0 | E21: 0 | F21: 0 | G21: 0 | H21: 0 | I21: 0 | J21: 0 | K21: 0 | L21: 0
A22: 46030 | B22: Other | D22: 0 | E22: 0 | F22: 0 | G22: 0 | H22: 0 | I22: 0 | J22: 0 | K22: 0 | L22: 0
A23: 46028 | B23: Cash | D23: 0 | E23: 0 | F23: 0 | G23: 0 | H23: 0 | I23: 0 | J23: 0 | K23: 0 | L23: 0
A24: 46028 | B24: Credit/debit | D24: 2 | E24: 193.4 | F24: 36 | G24: 0 | H24: 23.55 | I24: 0 | J24: 0 | K24: 36 | L24: 229.4 | M24: 21.2
A25: 46028 | B25: Credit/debit | C25: VISA | D25: 2 | E25: 193.4 | F25: 36 | G25: 0 | H25: 23.55 | I25: 0 | J25: 0 | K25: 36 | L25: 229.4 | M25: 21.2
A26: 46028 | B26: Gift Card | D26: 0 | E26: 0 | F26: 0 | G26: 0 | H26: 0 | I26: 0 | J26: 0 | K26: 0 | L26: 0
A27: 46028 | B27: Other | D27: 0 | E27: 0 | F27: 0 | G27: 0 | H27: 0 | I27: 0 | J27: 0 | K27: 0 | L27: 0
A28: 46026 | B28: Cash | D28: 0 | E28: 0 | F28: 0 | G28: 0 | H28: 0 | I28: 0 | J28: 0 | K28: 0 | L28: 0
A29: 46026 | B29: Credit/debit | D29: 3 | E29: 493.72 | F29: 81.47 | G29: 0 | H29: 49.58 | I29: 0 | J29: 0 | K29: 81.47 | L29: 575.19 | M29: 18.3
A30: 46026 | B30: Credit/debit | C30: DISCOVER | D30: 1 | E30: 169.03 | F30: 25 | G30: 0 | H30: 15.71 | I30: 0 | J30: 0 | K30: 25 | L30: 194.03 | M30: 16.3
A31: 46026 | B31: Credit/debit | C31: VISA | D31: 2 | E31: 324.69 | F31: 56.47 | G31: 0 | H31: 33.87 | I31: 0 | J31: 0 | K31: 56.47 | L31: 381.16 | M31: 19.4
A32: 46026 | B32: Gift Card | D32: 0 | E32: 0 | F32: 0 | G32: 0 | H32: 0 | I32: 0 | J32: 0 | K32: 0 | L32: 0
A33: 46026 | B33: Other | D33: 3 | E33: 217.81 | F33: 44.56 | G33: 0 | H33: 24.86 | I33: 0 | J33: 0 | K33: 44.56 | L33: 262.37 | M33: 23.1
A34: 46026 | B34: Other | C34: inkind | D34: 3 | E34: 217.81 | F34: 44.56 | G34: 0 | H34: 24.86 | I34: 0 | J34: 0 | K34: 44.56 | L34: 262.37 | M34: 23.1
A35: 46025 | B35: Cash | D35: 38 | E35: 1048.43 | F35: 0 | G35: 25.19 | H35: 182.74 | I35: 0 | J35: 0 | K35: 0 | L35: 1073.62 | M35: 2.9
A36: 46025 | B36: Credit/debit | D36: 166 | E36: 6678.02 | F36: 568.21 | G36: 843.78 | H36: 1115.1 | I36: 0 | J36: 0 | K36: 568.21 | L36: 8090.01 | M36: 25.4
A37: 46025 | B37: Credit/debit | C37: AMEX | D37: 12 | E37: 1138.69 | F37: 97.14 | G37: 144.34 | H37: 224.88 | I37: 0 | J37: 0 | K37: 97.14 | L37: 1380.17 | M37: 26.4
A38: 46025 | B38: Credit/debit | C38: DISCOVER | D38: 2 | E38: 102.78 | F38: 1 | G38: 16.5 | H38: 16.9 | I38: 0 | J38: 0 | K38: 1 | L38: 120.28 | M38: 20.4
A39: 46025 | B39: Credit/debit | C39: MASTERCARD | D39: 64 | E39: 2143.06 | F39: 205.19 | G39: 281.27 | H39: 360.58 | I39: 0 | J39: 0 | K39: 205.19 | L39: 2629.52 | M39: 27.3
A40: 46025 | B40: Credit/debit | C40: VISA | D40: 88 | E40: 3293.49 | F40: 264.88 | G40: 401.67 | H40: 512.74 | I40: 0 | J40: 0 | K40: 264.88 | L40: 3960.04 | M40: 24
...

Sheet Sales_Revenue
A1: Date | B1: Net sales | C1: Gratuity | D1: Tax amount | E1: Fundraising Contributions | F1: Fundraising Contribution Refunds | G1: Tips | H1: Deferred (gift cards) | I1: Deferred (house accounts) | J1: Deferred (other) | K1: deferredTaxAmount | L1: Paid in total | M1: Total
A2: 46026 | B2: 637.09 | C2: 0 | D2: 74.44 | G2: 126.03 | K2: 0 | L2: 0 | M2: 837.56
A3: 46022 | B3: 16960.47 | C3: 2161.35 | D3: 3233.85 | G3: 1284.1 | K3: 0 | L3: 0 | M3: 23639.77
A4: 46024 | B4: 1639.31 | C4: 108.06 | D4: 228.69 | G4: 215.68 | K4: 0 | L4: 0 | M4: 2191.74
A5: 46025 | B5: 6428.61 | C5: 868.97 | D5: 1297.84 | G5: 568.21 | K5: 0 | L5: 0 | M5: 9163.63
A6: 46028 | B6: 169.85 | C6: 0 | D6: 23.55 | G6: 36 | K6: 0 | L6: 0 | M6: 229.4
A7: 46030 | B7: 13 | C7: 0 | D7: 2.53 | G7: 5 | K7: 0 | L7: 0 | M7: 20.53
A8: 46031 | B8: 889.23 | C8: 89.06 | D8: 135.56 | G8: 44.58 | K8: 0 | L8: 0 | M8: 1158.43
A9: 46032 | B9: 6129.34 | C9: 850.33 | D9: 1163.74 | G9: 514.41 | K9: 0 | L9: 0 | M9: 8657.82
A10: 46021 | B10: 1804.54 | C10: 143.4 | D10: 232.76 | G10: 178.83 | K10: 0 | L10: 0 | M10: 2359.53

Sheet Sales_Category
A1: Date | B1: Sales category | C1: Items | D1: Net sales | E1: Discount amount | F1: Refund amount | G1: Gross sales | H1: Tax amount
A2: 46026 | B2: Bottled Beer | C2: 4 | D2: 31 | E2: 0 | F2: 0 | G2: 31 | H2: 3.17
A3: 46026 | B3: Food | C3: 19 | D3: 523.15 | E3: 0 | F3: 0 | G3: 523.15 | H3: 53.61
A4: 46026 | B4: Liquor | C4: 3 | D4: 61 | E4: 0 | F4: 0 | G4: 61 | H4: 15.4
A5: 46026 | B5: NA Beverage | C5: 3 | D5: 9 | E5: 0 | F5: 0 | G5: 9 | H5: 0.93
A6: 46026 | B6: Non-Grat Svc Charges | C6: 3 | D6: 12.94 | E6: 0 | F6: 0 | G6: 12.94 | H6: 1.33
A7: 46022 | B7: Bottled Beer | C7: 215 | D7: 1937 | E7: 18 | F7: 0 | G7: 1955 | H7: 199.01
A8: 46022 | B8: Food | C8: 149 | D8: 3886.04 | E8: 419.03 | F8: 0 | G8: 4305.07 | H8: 398.36
A9: 46022 | B9: Liquor | C9: 585 | D9: 10690.55 | E9: 487.55 | F9: 0 | G9: 11178.1 | H9: 2558.66
A10: 46022 | B10: NA Beverage | C10: 10 | D10: 33 | E10: 0 | F10: 0 | G10: 33 | H10: 3.4
A11: 46022 | B11: Non-Grat Svc Charges | C11: 96 | D11: 201.18 | E11: 0 | F11: 0 | G11: 201.18 | H11: 20.71
A12: 46022 | B12: Wine | C12: 14 | D12: 212.7 | E12: 24.3 | F12: 0 | G12: 237 | H12: 53.71
A13: 46024 | B13: Bottled Beer | C13: 5 | D13: 45 | E13: 0 | F13: 0 | G13: 45 | H13: 4.6
... A47: 46021 | B47: Wine | C47: 7 | D47: 98 | E47: 0 | F47: 0 | G47: 98 | H47: 24.75

Sheet Sales_Daypart
A1: Date | B1: Service / day part | C1: Orders | D1: Net sales | E1: Discount amount | F1: Refund amount | G1: Gross sales | H1: Tax amount
A2: 46026 | B2: Dinner | C2: 4 | D2: 637.09 | E2: 0 | F2: 0 | G2: 637.09 | H2: 74.44
A3: 46022 | B3: Dinner | C3: 31 | D3: 5763.03 | E3: 635.5 | F3: 0 | G3: 6398.53 | H3: 861.95
A4: 46022 | B4: Late Night | C4: 340 | D4: 11119.49 | E4: 313.38 | F4: 0 | G4: 11432.87 | H4: 2363.91
A5: 46022 | B5: No Service | C5: 1 | D5: 77.95 | E5: 0 | F5: 0 | G5: 77.95 | H5: 7.99
A6: 46024 | B6: Dinner | C6: 9 | D6: 1639.31 | E6: 0 | F6: 0 | G6: 1639.31 | H6: 228.69
A7: 46025 | B7: Brunch | C7: 4 | D7: 271.61 | E7: 4.89 | F7: 0 | G7: 276.5 | H7: 36.67
A8: 46025 | B8: Dinner | C8: 5 | D8: 360.27 | E8: 35.95 | F8: 0 | G8: 396.22 | H8: 52.82
A9: 46025 | B9: Late Night | C9: 190 | D9: 5796.73 | E9: 723.03 | F9: 0 | G9: 6519.76 | H9: 1208.35
A10: 46028 | B10: Dinner | C10: 2 | D10: 169.85 | E10: 0 | F10: 0 | G10: 169.85 | H10: 23.55
A11: 46030 | B11: Dinner | C11: 1 | D11: 13 | E11: 0 | F11: 0 | G11: 13 | H11: 2.53
A12: 46031 | B12: Dinner | C12: 6 | D12: 889.23 | E12: 28.5 | F12: 0 | G12: 917.73 | H12: 135.56
A13: 46032 | B13: Brunch | C13: 9 | D13: 1061.87 | E13: 2.9 | F13: 0 | G13: 1064.77 | H13: 163.63
... A17: 46021 | B17: Late Night | C17: 1 | D17: 29.87 | E17: 0 | F17: 0 | G17: 29.87 | H17: 3.06

Sheet Labor_Input
A1: Date | B1: Employee | C1: Job Title | D1: Clasification | E1: Regular Hours | F1: Overtime Hours | G1: Hourly Rate | H1: Regular Pay | I1: Overtime Pay | J1: Total Pay | K1: Net Sales

Sheet COGS_Input
A1: Week_Ending_Date | B1: Category | C1: Vendor | D1: Beginning_Inventory | E1: Purchases | F1: Ending_Inventory | G1: Total_Cost | H1: Helper_Key | J1: Match_Row
H2: Select Week Ending Date: | I2: 46041 | J2: (Format: YYYY-MM-DD or use Excel date picker)
A4: =IF($I$2<>"", $I$2, "") | B4: Food + NA Beverage | C4: Sysco | G4: =IF(AND(ISNUMBER(D4), ISNUMBER(E4), ISNUMBER(F4)), D4+E4-F4, "") | H4: =B4&"|"&C4
A5: =IF($I$2<>"", $I$2, "") | B5: Food + NA Beverage | C5: Creation Garden (WOW) | G5: =IF(AND(ISNUMBER(D5), ISNUMBER(E5), ISNUMBER(F5)), D5+E5-F5, "") | H5: =B5&"|"&C5
A6: =IF($I$2<>"", $I$2, "") | B6: Food + NA Beverage | C6: Restaurant Depot | G6: =IF(AND(ISNUMBER(D6), ISNUMBER(E6), ISNUMBER(F6)), D6+E6-F6, "") | H6: =B6&"|"&C6
A7: =IF($I$2<>"", $I$2, "") | B7: Food + NA Beverage | C7: Others | G7: =IF(AND(ISNUMBER(D7), ISNUMBER(E7), ISNUMBER(F7)), D7+E7-F7, "") | H7: =B7&"|"&C7
A8: =IF($I$2<>"", $I$2, "") | B8: Liquor + Wine | C8: Athens | G8: =IF(AND(ISNUMBER(D8), ISNUMBER(E8), ISNUMBER(F8)), D8+E8-F8, "") | H8: =B8&"|"&C8
A9: =IF($I$2<>"", $I$2, "") | B9: Liquor + Wine | C9: Lipman Brothers | G9: =IF(AND(ISNUMBER(D9), ISNUMBER(E9), ISNUMBER(F9)), D9+E9-F9, "") | H9: =B9&"|"&C9
A10: =IF($I$2<>"", $I$2, "") | B10: Liquor + Wine | C10: Best Brands | G10: =IF(AND(ISNUMBER(D10), ISNUMBER(E10), ISNUMBER(F10)), D10+E10-F10, "") | H10: =B10&"|"&C10
A11: =IF($I$2<>"", $I$2, "") | B11: Liquor + Wine | C11: Tennessee Distributors | G11: =IF(AND(ISNUMBER(D11), ISNUMBER(E11), ISNUMBER(F11)), D11+E11-F11, "") | H11: =B11&"|"&C11
A12: =IF($I$2<>"", $I$2, "") | B12: Liquor + Wine | C12: Empire | G12: =IF(AND(ISNUMBER(D12), ISNUMBER(E12), ISNUMBER(F12)), D12+E12-F12, "") | H12: =B12&"|"&C12
A13: =IF($I$2<>"", $I$2, "") | B13: Liquor + Wine | C13: Others | G13: =IF(AND(ISNUMBER(D13), ISNUMBER(E13), ISNUMBER(F13)), D13+E13-F13, "") | H13: =B13&"|"&C13
A14: =IF($I$2<>"", $I$2, "") | B14: Beer | C14: DET | G14: =IF(AND(ISNUMBER(D14), ISNUMBER(E14), ISNUMBER(F14)), D14+E14-F14, "") | H14: =B14&"|"&C14
A15: =IF($I$2<>"", $I$2, "") | B15: Beer | C15: Ajax Turner | G15: =IF(AND(ISNUMBER(D15), ISNUMBER(E15), ISNUMBER(F15)), D15+E15-F15, "") | H15: =B15&"|"&C15
... A20: =IF($I$2<>"", $I$2, "") | B20: Retail | C20: Others | G20: =IF(AND(ISNUMBER(D20), ISNUMBER(E20), ISNUMBER(F20)), D20+E20-F20, "") | H20: =B20&"|"&C20
A21: INSTRUCTIONS: 1) Select/enter week ending date in cell I2 2) Enter values in template rows 4-20 3) Select rows 4-20 (template), Copy 4) Scroll to week section below, find/create week section, Paste as VALUES 5) To edit existing week: Select that week date in I2, copy week data back to template, edit, then paste back
A22: [COPY TEMPLATE →] Then paste below in appropriate week section
A24: Week Ending: 2026-01-12
A25: 46034 | B25: Food + NA Beverage | C25: Sysco | D25: 30 | E25: 50 | F25: 10 | G25: =IF(AND(ISNUMBER(D25), ISNUMBER(E25), ISNUMBER(F25)), D25+E25-F25, "")
A26: 46034 | B26: Food + NA Beverage | C26: Creation Garden (WOW) | D26: 40 | E26: 100 | F26: 30 | G26: =IF(AND(ISNUMBER(D26), ISNUMBER(E26), ISNUMBER(F26)), D26+E26-F26, "")
A27: 46034 | B27: Food + NA Beverage | C27: Restaurant Depot | G27: =IF(AND(ISNUMBER(D27), ISNUMBER(E27), ISNUMBER(F27)), D27+E27-F27, "")
A28: 46034 | B28: Food + NA Beverage | C28: Others | G28: =IF(AND(ISNUMBER(D28), ISNUMBER(E28), ISNUMBER(F28)), D28+E28-F28, "")
A29: 46034 | B29: Liquor + Wine | C29: Athens | G29: =IF(AND(ISNUMBER(D29), ISNUMBER(E29), ISNUMBER(F29)), D29+E29-F29, "")
A30: 46034 | B30: Liquor + Wine | C30: Lipman Brothers | G30: =IF(AND(ISNUMBER(D30), ISNUMBER(E30), ISNUMBER(F30)), D30+E30-F30, "")
A31: 46034 | B31: Liquor + Wine | C31: Best Brands | G31: =IF(AND(ISNUMBER(D31), ISNUMBER(E31), ISNUMBER(F31)), D31+E31-F31, "")
A32: 46034 | B32: Liquor + Wine | C32: Tennessee Distributors | G32: =IF(AND(ISNUMBER(D32), ISNUMBER(E32), ISNUMBER(F32)), D32+E32-F32, "")
A33: 46034 | B33: Liquor + Wine | C33: Empire | G33: =IF(AND(ISNUMBER(D33), ISNUMBER(E33), ISNUMBER(F33)), D33+E33-F33, "")
A34: 46034 | B34: Liquor + Wine | C34: Others | G34: =IF(AND(ISNUMBER(D34), ISNUMBER(E34), ISNUMBER(F34)), D34+E34-F34, "")
A35: 46034 | B35: Beer | C35: DET | G35: =IF(AND(ISNUMBER(D35), ISNUMBER(E35), ISNUMBER(F35)), D35+E35-F35, "")
A36: 46034 | B36: Beer | C36: Ajax Turner | G36: =IF(AND(ISNUMBER(D36), ISNUMBER(E36), ISNUMBER(F36)), D36+E36-F36, "")
A37: 46034 | B37: Beer | C37: Bounty Bev | G37: =IF(AND(ISNUMBER(D37), ISNUMBER(E37), ISNUMBER(F37)), D37+E37-F37, "")
A38: 46034 | B38: Beer | C38: Others | G38: =IF(AND(ISNUMBER(D38), ISNUMBER(E38), ISNUMBER(F38)), D38+E38-F38, "")
... A41: 46034 | B41: Retail | C41: Others | G41: =IF(AND(ISNUMBER(D41), ISNUMBER(E41), ISNUMBER(F41)), D41+E41-F41, "")
A42: Week Ending: 2026-01-05
A43: 46027 | B43: Food + NA Beverage | C43: Sysco | D43: 10 | E43: 20 | F43: 8 | G43: =IF(AND(ISNUMBER(D43), ISNUMBER(E43), ISNUMBER(F43)), D43+E43-F43, "")
A44: 46027 | B44: Food + NA Beverage | C44: Creation Garden (WOW) | D44: 10 | E44: 20 | F44: 8 | G44: =IF(AND(ISNUMBER(D44), ISNUMBER(E44), ISNUMBER(F44)), D44+E44-F44, "")
A45: 46027 | B45: Food + NA Beverage | C45: Restaurant Depot | D45: 10 | E45: 20 | F45: 8 | G45: =IF(AND(ISNUMBER(D45), ISNUMBER(E45), ISNUMBER(F45)), D45+E45-F45, "")
A46: 46027 | B46: Food + NA Beverage | C46: Others | G46: =IF(AND(ISNUMBER(D46), ISNUMBER(E46), ISNUMBER(F46)), D46+E46-F46, "")
A47: 46027 | B47: Liquor + Wine | C47: Athens | G47: =IF(AND(ISNUMBER(D47), ISNUMBER(E47), ISNUMBER(F47)), D47+E47-F47, "")
A48: 46027 | B48: Liquor + Wine | C48: Lipman Brothers | G48: =IF(AND(ISNUMBER(D48), ISNUMBER(E48), ISNUMBER(F48)), D48+E48-F48, "")
...

Sheet Direct_NonControllable
A1: Month | B1: Accounting and legal Services | C1: Admin and General | D1: Administrative | E1: Advertising & Marketing | F1: Auto Chlor / dishwasher | G1: Bank Charges & Fees | H1: Car & Truck/ Gas, Parking expenses | I1: Comcast/ Internet | J1: Credit Card Fees | K1: Credit Card Processing Fees | L1: Electricity | M1: Facility expenses | N1: Fintech Charges | O1: Fire inspection/Hood cleaning | P1: Insurance | Q1: Job Supplies bar and kitchen | R1: Lenin | S1: Licenses and permits | T1: Live Band | U1: Meals & Entertainment | V1: Music and Entertainments | W1: Nca Alarm Co. | X1: Non Controllable expenses | Y1: Occupancy | Z1: Office Supplies & Software | AA1: Operating Expenses | AB1: Over Draft Fees | AC1: QuickBooks Payments Fees | AD1: Rent & Lease | AE1: Repairs & Maintenance/ Renovation | AF1: Sp+ Property tax + Water+Trash | AG1: Toast Pos Software Monthly fee | AH1: Total for Direct Operation Expences(DOE) | AI1: Total for Income Taxes Paid | AJ1: Total for Non Controllable expenses | AK1: Total for Occupancy | AL1: Travel | AM1: Uncategorized Expense | AN1: Utilities | AO1: Window Cleaning | AP1: Total

Sheet Targets_Reference
A1: Metric | B1: Target_Value | C1: Unit
A2: Food_Cost_Pct | B2: 0.25 | C2: Percent
A3: Liquor_Cost_Pct | B3: 0.12 | C3: Percent
A4: Beer_Cost_Pct | B4: 0.15 | C4: Percent
A5: COGS_Pct | B5: 0.15 | C5: Percent
A6: Labor_Pct | B6: 0.25 | C6: Percent
A7: FOH_Pct | B7: 0.1 | C7: Percent
A8: BOH_Pct | B8: 0.1 | C8: Percent
A9: Management_Pct | B9: 0.1 | C9: Percent
A10: Prime_Cost_Pct | B10: 0.45 | C10: Percent

Sheet COGS_Vendor_Lookup
A1: Category | B1: Vendor | C1: Active
A2: Food + NA Beverage | B2: Sysco | C2: Y
A3: Food + NA Beverage | B3: Creation Garden (WOW) | C3: Y
A4: Food + NA Beverage | B4: Restaurant Depot | C4: Y
A5: Food + NA Beverage | B5: Others | C5: Y
A6: Liquor + Wine | B6: Athens | C6: Y
A7: Liquor + Wine | B7: Lipman Brothers | C7: Y
A8: Liquor + Wine | B8: Best Brands | C8: Y
A9: Liquor + Wine | B9: Tennessee Distributors | C9: Y
A10: Liquor + Wine | B10: Empire | C10: Y
A11: Liquor + Wine | B11: Others | C11: Y
A12: Beer | B12: DET | C12: Y
... A18: Retail | B18: Others | C18: Y

Sheet Job_Classification_Lookup
A1: Job_Title | B1: Classification
A2: Cook | B2: BOH
A3: Dishwasher | B3: BOH
A4: BOH Support | B4: BOH
A5: Kitchen Manager | B5: BOH
A6: Server | B6: FOH
A7: Bartender | B7: FOH
A8: Event Server | B8: FOH
A9: Event Bartender | B9: FOH
A10: Event bartender | B10: FOH
A11: Floor Manager | B11: FOH
A12: Shift Manager | B12: FOH
... A19: GM | B19: Management

Sheet Data_Aggregation
A1: Week_Ending_Date | B1: Net_Sales_Total | C1: Food_Sales | D1: Liquor_Sales | E1: Beer_Sales | F1: Food_COGS | G1: Liquor_COGS | H1: Beer_COGS | I1: Total_COGS | J1: FOH_Labor | K1: BOH_Labor | L1: Management_Labor | M1: Security_Labor | N1: Labor_Tax | O1: Total_Labor | P1: Week_Number | Q1: Year

Sheet Category Daily Ops
